Workbook

Sheet Sheet1
A1: email_petugas_lapangan | B1: petugas_pemeriksa | C1: email_pemeriksa | D1: petugas_taskforce | E1: email_taskforce
A2: rifnisikome452@gmail.com | B2: Nur Ain Entengo | C2: nurainentengo@yahoo.com | D2: Aji | E2: Aji@bps.go.id
A3: tegarsani544@gmail.com | B3: Nur Ain Entengo | C3: nurainentengo@yahoo.com | D3: Aji | E3: Aji@bps.go.id
A4: maurisiolungkang750@gmail.com | B4: Nur Ain Entengo | C4: nurainentengo@yahoo.com | D4: Aji | E4: Aji@bps.go.id
A5: albertangaghunting@gmail.com | B5: Nur Ain Entengo | C5: nurainentengo@yahoo.com | D5: Aji | E5: Aji@bps.go.id
A6: adrianussandil04@gmail.com | B6: Nur Ain Entengo | C6: nurainentengo@yahoo.com | D6: Aji | E6: Aji@bps.go.id
A7: savitriusman4@gmail.com | B7: Nur Ain Entengo | C7: nurainentengo@yahoo.com | D7: Aji | E7: Aji@bps.go.id
A8: oveliasahoa6@gmail.com | B8: Erlinda Kirojan | C8: erlindakirojan83@gmail.com | D8: Alan | E8: Alan@bps.go.id
A9: makikehang10@gmail.com | B9: Erlinda Kirojan | C9: erlindakirojan83@gmail.com | D9: Alan | E9: Alan@bps.go.id
A10: animonster023@gmail.com | B10: Erlinda Kirojan | C10: erlindakirojan83@gmail.com | D10: Alan | E10: Alan@bps.go.id
A11: SAFITRIAMIN7@GMAIL.COM | B11: Erlinda Kirojan | C11: erlindakirojan83@gmail.com | D11: Alan | E11: Alan@bps.go.id
A12: Mellymark90@gmail.com | B12: Erlinda Kirojan | C12: erlindakirojan83@gmail.com | D12: Alan | E12: Alan@bps.go.id
... A139: sianelegi2024@gmail.com | B139: Retnowati Sumelung | C139: retnowathy.sumelung@gmail.com | D139: Vera | E139: Vera@bps.go.id

Sheet region_summary (54)
A1: email | B1: regionCode | C1: total | D1: APPROVED BY Pengawas | E1: DRAFT | F1: EDITED BY Admin Kabupaten | G1: OPEN | H1: REJECTED BY Admin Kabupaten | I1: REJECTED BY Pengawas | J1: REVOKED BY Pengawas | K1: SUBMITTED BY Pencacah | L1: SUBMITTED RESPONDENT | M1: Column1
A2: ingkiriwangmey76@gmail.com | B2: 7.17201e+15 | C2: 132 | D2: 125 | E2: 1 | F2: 2 | G2: 2 | H2: 0 | I2: 0 | J2: 0 | K2: 2 | L2: 0 | M2: =region_summary__54[[#This Row],[REJECTED BY Admin Kabupaten]]+region_summary__54[[#This Row],[REJECTED BY Pengawas]] -> 0
A3: ingkiriwangmey76@gmail.com | B3: 7.17201e+15 | C3: 104 | D3: 92 | E3: 0 | F3: 3 | G3: 7 | H3: 0 | I3: 0 | J3: 0 | K3: 2 | L3: 0 | M3: =region_summary__54[[#This Row],[REJECTED BY Admin Kabupaten]]+region_summary__54[[#This Row],[REJECTED BY Pengawas]] -> 0
A4: ingkiriwangmey76@gmail.com | B4: 7.17201e+15 | C4: 102 | D4: 99 | E4: 2 | F4: 1 | G4: 0 | H4: 0 | I4: 0 | J4: 0 | K4: 0 | L4: 0 | M4: =region_summary__54[[#This Row],[REJECTED BY Admin Kabupaten]]+region_summary__54[[#This Row],[REJECTED BY Pengawas]] -> 0
A5: ingkiriwangmey76@gmail.com | B5: 7.17201e+15 | C5: 82 | D5: 39 | E5: 1 | F5: 0 | G5: 13 | H5: 0 | I5: 0 | J5: 0 | K5: 29 | L5: 0 | M5: =region_summary__54[[#This Row],[REJECTED BY Admin Kabupaten]]+region_summary__54[[#This Row],[REJECTED BY Pengawas]] -> 0
A6: ingkiriwangmey76@gmail.com | B6: 7.17201e+15 | C6: 81 | D6: 0 | E6: 20 | F6: 0 | G6: 17 | H6: 0 | I6: 0 | J6: 0 | K6: 44 | L6: 0 | M6: =region_summary__54[[#This Row],[REJECTED BY Admin Kabupaten]]+region_summary__54[[#This Row],[REJECTED BY Pengawas]] -> 0
A7: ingkiriwangmey76@gmail.com | B7: 7.17201e+15 | C7: 67 | D7: 0 | E7: 3 | F7: 0 | G7: 13 | H7: 0 | I7: 0 | J7: 0 | K7: 51 | L7: 0 | M7: =region_summary__54[[#This Row],[REJECTED BY Admin Kabupaten]]+region_summary__54[[#This Row],[REJECTED BY Pengawas]] -> 0
A8: ingkiriwangmey76@gmail.com | B8: 7.17201e+15 | C8: 61 | D8: 0 | E8: 0 | F8: 0 | G8: 61 | H8: 0 | I8: 0 | J8: 0 | K8: 0 | L8: 0 | M8: =region_summary__54[[#This Row],[REJECTED BY Admin Kabupaten]]+region_summary__54[[#This Row],[REJECTED BY Pengawas]] -> 0
A9: ingkiriwangmey76@gmail.com | B9: 7.17201e+15 | C9: 38 | D9: 0 | E9: 0 | F9: 0 | G9: 38 | H9: 0 | I9: 0 | J9: 0 | K9: 0 | L9: 0 | M9: =region_summary__54[[#This Row],[REJECTED BY Admin Kabupaten]]+region_summary__54[[#This Row],[REJECTED BY Pengawas]] -> 0
A10: shyntiamangosa@gmail.com | B10: 7.17201e+15 | C10: 198 | D10: 187 | E10: 0 | F10: 4 | G10: 6 | H10: 0 | I10: 0 | J10: 0 | K10: 1 | L10: 0 | M10: =region_summary__54[[#This Row],[REJECTED BY Admin Kabupaten]]+region_summary__54[[#This Row],[REJECTED BY Pengawas]] -> 0
A11: shyntiamangosa@gmail.com | B11: 7.17201e+15 | C11: 191 | D11: 32 | E11: 0 | F11: 1 | G11: 37 | H11: 0 | I11: 0 | J11: 0 | K11: 121 | L11: 0 | M11: =region_summary__54[[#This Row],[REJECTED BY Admin Kabupaten]]+region_summary__54[[#This Row],[REJECTED BY Pengawas]] -> 0
A12: shyntiamangosa@gmail.com | B12: 7.17201e+15 | C12: 160 | D12: 158 | E12: 0 | F12: 1 | G12: 1 | H12: 0 | I12: 0 | J12: 0 | K12: 0 | L12: 0 | M12: =region_summary__54[[#This Row],[REJECTED BY Admin Kabupaten]]+region_summary__54[[#This Row],[REJECTED BY Pengawas]] -> 0
A13: shyntiamangosa@gmail.com | B13: 7.17201e+15 | C13: 71 | D13: 0 | E13: 2 | F13: 0 | G13: 44 | H13: 0 | I13: 0 | J13: 0 | K13: 25 | L13: 0 | M13: =region_summary__54[[#This Row],[REJECTED BY Admin Kabupaten]]+region_summary__54[[#This Row],[REJECTED BY Pengawas]] -> 0
... A1056: mfeibyola@gmail.com | B1056: 7.172012e+15 | C1056: 88 | D1056: 69 | E1056: 2 | F1056: 0 | G1056: 17 | H1056: 0 | I1056: 0 | J1056: 0 | K1056: 0 | L1056: 0 | M1056: =region_summary__54[[#This Row],[REJECTED BY Admin Kabupaten]]+region_summary__54[[#This Row],[REJECTED BY Pengawas]] -> 0

Sheet DATA
A1: email | B1: regionCode | C1: total | D1: APPROVED BY Pengawas | E1: DRAFT | F1: OPEN | G1: REJECTED BY Pengawas | H1: REVOKED BY Pengawas | I1: SUBMITTED BY Pencacah | J1: SUBMITTED RESPONDENT | K1: jumlah_keluarga_tidak_ditemukan | L1: jumlah_usaha_tidak_ditemukan | M1: jumlah_bangunan_kosong | N1: TDK
A2: devitasimpaen11@gmail.com | B2: 7172010008000100 | C2: =VLOOKUP(B2,raw!A:K,11,0) -> 102 | D2: =VLOOKUP(B2,raw!A:K,3,0)+VLOOKUP(B2,raw!A:K,7,0) -> 102 | E2: =VLOOKUP(B2,raw!A:K,4,0) -> 0 | F2: =VLOOKUP(B2,raw!A:K,5,0) -> 0 | G2: =VLOOKUP(B2,raw!A:K,2,0)+VLOOKUP(B2,raw!A:K,10,0) -> 0 | H2: =VLOOKUP(B2,raw!A:K,6,0) -> 0 | I2: =VLOOKUP(B2,raw!A:K,9,0) -> 0 | J2: =VLOOKUP(B2,raw!A:K,8,0) -> 0 | K2: =_xlfn.IFNA(VLOOKUP(B2,TDK!A:C,2,0),0) -> 41 | L2: =_xlfn.IFNA(VLOOKUP(B2,TDK!A:C,3,0),0) -> 4 | M2: =_xlfn.IFNA(VLOOKUP(B2,TDK!F:G,2,0),0) -> 4 | N2: =SUM(K2:M2) -> 49
A3: glaudiasasindua@gmail.com | B3: 7172010008000200 | C3: =VLOOKUP(B3,raw!A:K,11,0) -> 73 | D3: =VLOOKUP(B3,raw!A:K,3,0)+VLOOKUP(B3,raw!A:K,7,0) -> 73 | E3: =VLOOKUP(B3,raw!A:K,4,0) -> 0 | F3: =VLOOKUP(B3,raw!A:K,5,0) -> 0 | G3: =VLOOKUP(B3,raw!A:K,2,0)+VLOOKUP(B3,raw!A:K,10,0) -> 0 | H3: =VLOOKUP(B3,raw!A:K,6,0) -> 0 | I3: =VLOOKUP(B3,raw!A:K,9,0) -> 0 | J3: =VLOOKUP(B3,raw!A:K,8,0) -> 0 | K3: =_xlfn.IFNA(VLOOKUP(B3,TDK!A:C,2,0),0) -> 24 | L3: =_xlfn.IFNA(VLOOKUP(B3,TDK!A:C,3,0),0) -> 1 | M3: =_xlfn.IFNA(VLOOKUP(B3,TDK!F:G,2,0),0) -> 0 | N3: =SUM(K3:M3) -> 25
A4: glaudiasasindua@gmail.com | B4: 7172010008000300 | C4: =VLOOKUP(B4,raw!A:K,11,0) -> 43 | D4: =VLOOKUP(B4,raw!A:K,3,0)+VLOOKUP(B4,raw!A:K,7,0) -> 43 | E4: =VLOOKUP(B4,raw!A:K,4,0) -> 0 | F4: =VLOOKUP(B4,raw!A:K,5,0) -> 0 | G4: =VLOOKUP(B4,raw!A:K,2,0)+VLOOKUP(B4,raw!A:K,10,0) -> 0 | H4: =VLOOKUP(B4,raw!A:K,6,0) -> 0 | I4: =VLOOKUP(B4,raw!A:K,9,0) -> 0 | J4: =VLOOKUP(B4,raw!A:K,8,0) -> 0 | K4: =_xlfn.IFNA(VLOOKUP(B4,TDK!A:C,2,0),0) -> 17 | L4: =_xlfn.IFNA(VLOOKUP(B4,TDK!A:C,3,0),0) -> 0 | M4: =_xlfn.IFNA(VLOOKUP(B4,TDK!F:G,2,0),0) -> 0 | N4: =SUM(K4:M4) -> 17
A5: glaudiasasindua@gmail.com | B5: 7172010008000400 | C5: =VLOOKUP(B5,raw!A:K,11,0) -> 71 | D5: =VLOOKUP(B5,raw!A:K,3,0)+VLOOKUP(B5,raw!A:K,7,0) -> 71 | E5: =VLOOKUP(B5,raw!A:K,4,0) -> 0 | F5: =VLOOKUP(B5,raw!A:K,5,0) -> 0 | G5: =VLOOKUP(B5,raw!A:K,2,0)+VLOOKUP(B5,raw!A:K,10,0) -> 0 | H5: =VLOOKUP(B5,raw!A:K,6,0) -> 0 | I5: =VLOOKUP(B5,raw!A:K,9,0) -> 0 | J5: =VLOOKUP(B5,raw!A:K,8,0) -> 0 | K5: =_xlfn.IFNA(VLOOKUP(B5,TDK!A:C,2,0),0) -> 22 | L5: =_xlfn.IFNA(VLOOKUP(B5,TDK!A:C,3,0),0) -> 7 | M5: =_xlfn.IFNA(VLOOKUP(B5,TDK!F:G,2,0),0) -> 0 | N5: =SUM(K5:M5) -> 29
A6: glaudiasasindua@gmail.com | B6: 7172010008000500 | C6: =VLOOKUP(B6,raw!A:K,11,0) -> 88 | D6: =VLOOKUP(B6,raw!A:K,3,0)+VLOOKUP(B6,raw!A:K,7,0) -> 88 | E6: =VLOOKUP(B6,raw!A:K,4,0) -> 0 | F6: =VLOOKUP(B6,raw!A:K,5,0) -> 0 | G6: =VLOOKUP(B6,raw!A:K,2,0)+VLOOKUP(B6,raw!A:K,10,0) -> 0 | H6: =VLOOKUP(B6,raw!A:K,6,0) -> 0 | I6: =VLOOKUP(B6,raw!A:K,9,0) -> 0 | J6: =VLOOKUP(B6,raw!A:K,8,0) -> 0 | K6: =_xlfn.IFNA(VLOOKUP(B6,TDK!A:C,2,0),0) -> 30 | L6: =_xlfn.IFNA(VLOOKUP(B6,TDK!A:C,3,0),0) -> 1 | M6: =_xlfn.IFNA(VLOOKUP(B6,TDK!F:G,2,0),0) -> 1 | N6: =SUM(K6:M6) -> 32
A7: glaudiasasindua@gmail.com | B7: 7172010008000600 | C7: =VLOOKUP(B7,raw!A:K,11,0) -> 144 | D7: =VLOOKUP(B7,raw!A:K,3,0)+VLOOKUP(B7,raw!A:K,7,0) -> 144 | E7: =VLOOKUP(B7,raw!A:K,4,0) -> 0 | F7: =VLOOKUP(B7,raw!A:K,5,0) -> 0 | G7: =VLOOKUP(B7,raw!A:K,2,0)+VLOOKUP(B7,raw!A:K,10,0) -> 0 | H7: =VLOOKUP(B7,raw!A:K,6,0) -> 0 | I7: =VLOOKUP(B7,raw!A:K,9,0) -> 0 | J7: =VLOOKUP(B7,raw!A:K,8,0) -> 0 | K7: =_xlfn.IFNA(VLOOKUP(B7,TDK!A:C,2,0),0) -> 49 | L7: =_xlfn.IFNA(VLOOKUP(B7,TDK!A:C,3,0),0) -> 1 | M7: =_xlfn.IFNA(VLOOKUP(B7,TDK!F:G,2,0),0) -> 1 | N7: =SUM(K7:M7) -> 51
A8: glaudiasasindua@gmail.com | B8: 7172010008000700 | C8: =VLOOKUP(B8,raw!A:K,11,0) -> 172 | D8: =VLOOKUP(B8,raw!A:K,3,0)+VLOOKUP(B8,raw!A:K,7,0) -> 172 | E8: =VLOOKUP(B8,raw!A:K,4,0) -> 0 | F8: =VLOOKUP(B8,raw!A:K,5,0) -> 0 | G8: =VLOOKUP(B8,raw!A:K,2,0)+VLOOKUP(B8,raw!A:K,10,0) -> 0 | H8: =VLOOKUP(B8,raw!A:K,6,0) -> 0 | I8: =VLOOKUP(B8,raw!A:K,9,0) -> 0 | J8: =VLOOKUP(B8,raw!A:K,8,0) -> 0 | K8: =_xlfn.IFNA(VLOOKUP(B8,TDK!A:C,2,0),0) -> 53 | L8: =_xlfn.IFNA(VLOOKUP(B8,TDK!A:C,3,0),0) -> 5 | M8: =_xlfn.IFNA(VLOOKUP(B8,TDK!F:G,2,0),0) -> 0 | N8: =SUM(K8:M8) -> 58
A9: shyntiamangosa@gmail.com | B9: 7172010008000800 | C9: =VLOOKUP(B9,raw!A:K,11,0) -> 154 | D9: =VLOOKUP(B9,raw!A:K,3,0)+VLOOKUP(B9,raw!A:K,7,0) -> 154 | E9: =VLOOKUP(B9,raw!A:K,4,0) -> 0 | F9: =VLOOKUP(B9,raw!A:K,5,0) -> 0 | G9: =VLOOKUP(B9,raw!A:K,2,0)+VLOOKUP(B9,raw!A:K,10,0) -> 0 | H9: =VLOOKUP(B9,raw!A:K,6,0) -> 0 | I9: =VLOOKUP(B9,raw!A:K,9,0) -> 0 | J9: =VLOOKUP(B9,raw!A:K,8,0) -> 0 | K9: =_xlfn.IFNA(VLOOKUP(B9,TDK!A:C,2,0),0) -> 39 | L9: =_xlfn.IFNA(VLOOKUP(B9,TDK!A:C,3,0),0) -> 7 | M9: =_xlfn.IFNA(VLOOKUP(B9,TDK!F:G,2,0),0) -> 19 | N9: =SUM(K9:M9) -> 65
A10: shyntiamangosa@gmail.com | B10: 7172010008000900 | C10: =VLOOKUP(B10,raw!A:K,11,0) -> 93 | D10: =VLOOKUP(B10,raw!A:K,3,0)+VLOOKUP(B10,raw!A:K,7,0) -> 93 | E10: =VLOOKUP(B10,raw!A:K,4,0) -> 0 | F10: =VLOOKUP(B10,raw!A:K,5,0) -> 0 | G10: =VLOOKUP(B10,raw!A:K,2,0)+VLOOKUP(B10,raw!A:K,10,0) -> 0 | H10: =VLOOKUP(B10,raw!A:K,6,0) -> 0 | I10: =VLOOKUP(B10,raw!A:K,9,0) -> 0 | J10: =VLOOKUP(B10,raw!A:K,8,0) -> 0 | K10: =_xlfn.IFNA(VLOOKUP(B10,TDK!A:C,2,0),0) -> 19 | L10: =_xlfn.IFNA(VLOOKUP(B10,TDK!A:C,3,0),0) -> 3 | M10: =_xlfn.IFNA(VLOOKUP(B10,TDK!F:G,2,0),0) -> 4 | N10: =SUM(K10:M10) -> 26
A11: shyntiamangosa@gmail.com | B11: 7172010008001000 | C11: =VLOOKUP(B11,raw!A:K,11,0) -> 205 | D11: =VLOOKUP(B11,raw!A:K,3,0)+VLOOKUP(B11,raw!A:K,7,0) -> 205 | E11: =VLOOKUP(B11,raw!A:K,4,0) -> 0 | F11: =VLOOKUP(B11,raw!A:K,5,0) -> 0 | G11: =VLOOKUP(B11,raw!A:K,2,0)+VLOOKUP(B11,raw!A:K,10,0) -> 0 | H11: =VLOOKUP(B11,raw!A:K,6,0) -> 0 | I11: =VLOOKUP(B11,raw!A:K,9,0) -> 0 | J11: =VLOOKUP(B11,raw!A:K,8,0) -> 0 | K11: =_xlfn.IFNA(VLOOKUP(B11,TDK!A:C,2,0),0) -> 45 | L11: =_xlfn.IFNA(VLOOKUP(B11,TDK!A:C,3,0),0) -> 5 | M11: =_xlfn.IFNA(VLOOKUP(B11,TDK!F:G,2,0),0) -> 20 | N11: =SUM(K11:M11) -> 70
A12: shyntiamangosa@gmail.com | B12: 7172010008001101 | C12: =VLOOKUP(B12,raw!A:K,11,0) -> 191 | D12: =VLOOKUP(B12,raw!A:K,3,0)+VLOOKUP(B12,raw!A:K,7,0) -> 191 | E12: =VLOOKUP(B12,raw!A:K,4,0) -> 0 | F12: =VLOOKUP(B12,raw!A:K,5,0) -> 0 | G12: =VLOOKUP(B12,raw!A:K,2,0)+VLOOKUP(B12,raw!A:K,10,0) -> 0 | H12: =VLOOKUP(B12,raw!A:K,6,0) -> 0 | I12: =VLOOKUP(B12,raw!A:K,9,0) -> 0 | J12: =VLOOKUP(B12,raw!A:K,8,0) -> 0 | K12: =_xlfn.IFNA(VLOOKUP(B12,TDK!A:C,2,0),0) -> 94 | L12: =_xlfn.IFNA(VLOOKUP(B12,TDK!A:C,3,0),0) -> 4 | M12: =_xlfn.IFNA(VLOOKUP(B12,TDK!F:G,2,0),0) -> 7 | N12: =SUM(K12:M12) -> 105
A13: devitasimpaen11@gmail.com | B13: 7172010008001102 | C13: =VLOOKUP(B13,raw!A:K,11,0) -> 144 | D13: =VLOOKUP(B13,raw!A:K,3,0)+VLOOKUP(B13,raw!A:K,7,0) -> 144 | E13: =VLOOKUP(B13,raw!A:K,4,0) -> 0 | F13: =VLOOKUP(B13,raw!A:K,5,0) -> 0 | G13: =VLOOKUP(B13,raw!A:K,2,0)+VLOOKUP(B13,raw!A:K,10,0) -> 0 | H13: =VLOOKUP(B13,raw!A:K,6,0) -> 0 | I13: =VLOOKUP(B13,raw!A:K,9,0) -> 0 | J13: =VLOOKUP(B13,raw!A:K,8,0) -> 0 | K13: =_xlfn.IFNA(VLOOKUP(B13,TDK!A:C,2,0),0) -> 16 | L13: =_xlfn.IFNA(VLOOKUP(B13,TDK!A:C,3,0),0) -> 0 | M13: =_xlfn.IFNA(VLOOKUP(B13,TDK!F:G,2,0),0) -> 16 | N13: =SUM(K13:M13) -> 32
... A1058: marsitaamala@gmail.com | B1058: 7172040013001200 | C1058: =VLOOKUP(B1058,raw!A:K,11,0) -> 67 | D1058: =VLOOKUP(B1058,raw!A:K,3,0)+VLOOKUP(B1058,raw!A:K,7,0) -> 46 | E1058: =VLOOKUP(B1058,raw!A:K,4,0) -> 0 | F1058: =VLOOKUP(B1058,raw!A:K,5,0) -> 0 | G1058: =VLOOKUP(B1058,raw!A:K,2,0)+VLOOKUP(B1058,raw!A:K,10,0) -> 0 | H1058: =VLOOKUP(B1058,raw!A:K,6,0) -> 1 | I1058: =VLOOKUP(B1058,raw!A:K,9,0) -> 20 | J1058: =VLOOKUP(B1058,raw!A:K,8,0) -> 0 | K1058: =_xlfn.IFNA(VLOOKUP(B1058,TDK!A:C,2,0),0) -> 7 | L1058: =_xlfn.IFNA(VLOOKUP(B1058,TDK!A:C,3,0),0) -> 4 | M1058: =_xlfn.IFNA(VLOOKUP(B1058,TDK!F:G,2,0),0) -> 5 | N1058: =SUM(K1058:M1058) -> 16

Sheet raw
A1: level_6_full_code | B1: REJECTED_Admin_Kabupaten | C1: APPROVED_Pengawas | D1: DRAFT | E1: OPEN | F1: REVOKED_Pengawas | G1: EDITED_Admin_Kabupaten | H1: SUBMITTED_RESPONDENT | I1: SUBMITTED_Pencacah | J1: REJECTED_Pengawas | K1: total_semua | L1: status
A2: 7172000000000000 | B2: 0 | C2: 0 | D2: 4 | E2: 5 | F2: 0 | G2: 0 | H2: 12 | I2: 0 | J2: 0 | K2: 21 | L2: =K2=SUM(B2:J2) -> TRUE
A3: 7172010008000100 | B3: 0 | C3: 102 | D3: 0 | E3: 0 | F3: 0 | G3: 0 | H3: 0 | I3: 0 | J3: 0 | K3: 102 | L3: =K3=SUM(B3:J3) -> TRUE
A4: 7172010008000200 | B4: 0 | C4: 71 | D4: 0 | E4: 0 | F4: 0 | G4: 2 | H4: 0 | I4: 0 | J4: 0 | K4: 73 | L4: =K4=SUM(B4:J4) -> TRUE
A5: 7172010008000300 | B5: 0 | C5: 43 | D5: 0 | E5: 0 | F5: 0 | G5: 0 | H5: 0 | I5: 0 | J5: 0 | K5: 43 | L5: =K5=SUM(B5:J5) -> TRUE
A6: 7172010008000400 | B6: 0 | C6: 66 | D6: 0 | E6: 0 | F6: 0 | G6: 5 | H6: 0 | I6: 0 | J6: 0 | K6: 71 | L6: =K6=SUM(B6:J6) -> TRUE
A7: 7172010008000500 | B7: 0 | C7: 87 | D7: 0 | E7: 0 | F7: 0 | G7: 1 | H7: 0 | I7: 0 | J7: 0 | K7: 88 | L7: =K7=SUM(B7:J7) -> TRUE
A8: 7172010008000600 | B8: 0 | C8: 144 | D8: 0 | E8: 0 | F8: 0 | G8: 0 | H8: 0 | I8: 0 | J8: 0 | K8: 144 | L8: =K8=SUM(B8:J8) -> TRUE
A9: 7172010008000700 | B9: 0 | C9: 172 | D9: 0 | E9: 0 | F9: 0 | G9: 0 | H9: 0 | I9: 0 | J9: 0 | K9: 172 | L9: =K9=SUM(B9:J9) -> TRUE
A10: 7172010008000800 | B10: 0 | C10: 153 | D10: 0 | E10: 0 | F10: 0 | G10: 1 | H10: 0 | I10: 0 | J10: 0 | K10: 154 | L10: =K10=SUM(B10:J10) -> TRUE
A11: 7172010008000900 | B11: 0 | C11: 92 | D11: 0 | E11: 0 | F11: 0 | G11: 1 | H11: 0 | I11: 0 | J11: 0 | K11: 93 | L11: =K11=SUM(B11:J11) -> TRUE
A12: 7172010008001000 | B12: 0 | C12: 201 | D12: 0 | E12: 0 | F12: 0 | G12: 4 | H12: 0 | I12: 0 | J12: 0 | K12: 205 | L12: =K12=SUM(B12:J12) -> TRUE
A13: 7172010008001101 | B13: 0 | C13: 189 | D13: 0 | E13: 0 | F13: 0 | G13: 2 | H13: 0 | I13: 0 | J13: 0 | K13: 191 | L13: =K13=SUM(B13:J13) -> TRUE
... A1062: 7172040013001200 | B1062: 0 | C1062: 46 | D1062: 0 | E1062: 0 | F1062: 1 | G1062: 0 | H1062: 0 | I1062: 20 | J1062: 0 | K1062: 67 | L1062: =K1062=SUM(B1062:J1062) -> TRUE

Sheet TDK
A1: level_6_full_code | B1: jumlah_keluarga_tidak_ditemukan | C1: jumlah_usaha_tidak_ditemukan | D1: total_record | F1: level_6_full_code | G1: jumlah_bangunan_kosong
A2: 7172000000000000 | B2: 0 | C2: 0 | D2: 16 | F2: 7172010008000100 | G2: 4
A3: 7172010008000100 | B3: 41 | C3: 4 | D3: 102 | F3: 7172010008000500 | G3: 1
A4: 7172010008000200 | B4: 24 | C4: 1 | D4: 73 | F4: 7172010008000600 | G4: 1
A5: 7172010008000300 | B5: 17 | C5: 0 | D5: 43 | F5: 7172010008000800 | G5: 19
A6: 7172010008000400 | B6: 22 | C6: 7 | D6: 71 | F6: 7172010008000900 | G6: 4
A7: 7172010008000500 | B7: 30 | C7: 1 | D7: 88 | F7: 7172010008001000 | G7: 20
A8: 7172010008000600 | B8: 49 | C8: 1 | D8: 144 | F8: 7172010008001101 | G8: 7
A9: 7172010008000700 | B9: 53 | C9: 5 | D9: 172 | F9: 7172010008001102 | G9: 16
A10: 7172010008000800 | B10: 39 | C10: 7 | D10: 160 | F10: 7172010008001200 | G10: 1
A11: 7172010008000900 | B11: 19 | C11: 3 | D11: 93 | F11: 7172010008001300 | G11: 4
A12: 7172010008001000 | B12: 45 | C12: 5 | D12: 205 | F12: 7172010008001400 | G12: 12
A13: 7172010008001101 | B13: 94 | C13: 4 | D13: 191 | F13: 7172010008001500 | G13: 2
... A981: 7172040004000500 | B981: 38 | C981: 0 | D981: 97 | F981: 7172040013001200 | G981: 5
A982: 7172040004000600 | B982: 43 | C982: 10 | D982: 137
A983: 7172040005000100 | B983: 14 | C983: 2 | D983: 62
A984: 7172040005000200 | B984: 31 | C984: 0 | D984: 203
A985: 7172040005000300 | B985: 10 | C985: 1 | D985: 49
A986: 7172040005000400 | B986: 22 | C986: 3 | D986: 119
A987: 7172040005000500 | B987: 5 | C987: 0 | D987: 30
A988: 7172040005000600 | B988: 17 | C988: 0 | D988: 44
A989: 7172040005000700 | B989: 13 | C989: 0 | D989: 65
A990: 7172040005000800 | B990: 7 | C990: 0 | D990: 48
A991: 7172040005000900 | B991: 11 | C991: 2 | D991: 60
A992: 7172040005001000 | B992: 11 | C992: 0 | D992: 49
A993: 7172040005001100 | B993: 20 | C993: 0 | D993: 59
... A1059: 7172040013001200 | B1059: 7 | C1059: 4 | D1059: 66

Sheet HARIAN
A1: NAMA PETUGAS | B1: PML | C1: TASKFORCE | D1: JABATAN | E1: 2 HARI LALU | F1: KEMARIN | G1: HARI INI | H1: PROGRESS | I1: STATUS
A2: Devita Maria Kristi Simpaen | B2: =VLOOKUP(A2,PPL!B:C,2,0) -> Erfina K. Lamaju | C2: =VLOOKUP(A2,PPL!B:D,3,0) -> Meidy | D2: PPL | E2: 685 | F2: 684 | G2: =VLOOKUP(A2,PPL!B:N,13,0) -> 686 | H2: =G2-F2 -> 2 | I2: =E2=G2 -> FALSE
A3: Glaudia Enjela Sasindua | B3: =VLOOKUP(A3,PPL!B:C,2,0) -> Marsila Mayanti Matiune | C3: =VLOOKUP(A3,PPL!B:D,3,0) -> Lasimran | D3: PPL | E3: 643 | F3: 643 | G3: =VLOOKUP(A3,PPL!B:N,13,0) -> 643 | H3: =G3-F3 -> 0 | I3: =E3=G3 -> TRUE
A4: Yunita Shyntia Mangosa | B4: =VLOOKUP(A4,PPL!B:C,2,0) -> Erfina K. Lamaju | C4: =VLOOKUP(A4,PPL!B:D,3,0) -> Meidy | D4: PPL | E4: 733 | F4: 733 | G4: =VLOOKUP(A4,PPL!B:N,13,0) -> 733 | H4: =G4-F4 -> 0 | I4: =E4=G4 -> TRUE
A5: Rini Yani Aalung | B5: =VLOOKUP(A5,PPL!B:C,2,0) -> Erfina K. Lamaju | C5: =VLOOKUP(A5,PPL!B:D,3,0) -> Meidy | D5: PPL | E5: 706 | F5: 706 | G5: =VLOOKUP(A5,PPL!B:N,13,0) -> 706 | H5: =G5-F5 -> 0 | I5: =E5=G5 -> TRUE
A6: Maliny Ocnelia Tumandung | B6: =VLOOKUP(A6,PPL!B:C,2,0) -> Erfina K. Lamaju | C6: =VLOOKUP(A6,PPL!B:D,3,0) -> Meidy | D6: PPL | E6: 813 | F6: 813 | G6: =VLOOKUP(A6,PPL!B:N,13,0) -> 817 | H6: =G6-F6 -> 4 | I6: =E6=G6 -> FALSE
A7: Sumirani Gude | B7: =VLOOKUP(A7,PPL!B:C,2,0) -> Erfina K. Lamaju | C7: =VLOOKUP(A7,PPL!B:D,3,0) -> Meidy | D7: PPL | E7: 656 | F7: 656 | G7: =VLOOKUP(A7,PPL!B:N,13,0) -> 656 | H7: =G7-F7 -> 0 | I7: =E7=G7 -> TRUE
A8: Meily Ingkiriwang | B8: =VLOOKUP(A8,PPL!B:C,2,0) -> Marsila Mayanti Matiune | C8: =VLOOKUP(A8,PPL!B:D,3,0) -> Lasimran | D8: PPL | E8: 733 | F8: 733 | G8: =VLOOKUP(A8,PPL!B:N,13,0) -> 733 | H8: =G8-F8 -> 0 | I8: =E8=G8 -> TRUE
A9: Misnawati Mustamin | B9: =VLOOKUP(A9,PPL!B:C,2,0) -> Erfina K. Lamaju | C9: =VLOOKUP(A9,PPL!B:D,3,0) -> Meidy | D9: PPL | E9: 782 | F9: 782 | G9: =VLOOKUP(A9,PPL!B:N,13,0) -> 781 | H9: =G9-F9 -> -1 | I9: =E9=G9 -> FALSE
A10: Gersony Sirus Kakondo | B10: =VLOOKUP(A10,PPL!B:C,2,0) -> Marsila Mayanti Matiune | C10: =VLOOKUP(A10,PPL!B:D,3,0) -> Lasimran | D10: PPL | E10: 734 | F10: 734 | G10: =VLOOKUP(A10,PPL!B:N,13,0) -> 734 | H10: =G10-F10 -> 0 | I10: =E10=G10 -> TRUE
A11: Tesalonika Lohige | B11: =VLOOKUP(A11,PPL!B:C,2,0) -> Marsila Mayanti Matiune | C11: =VLOOKUP(A11,PPL!B:D,3,0) -> Lasimran | D11: PPL | E11: 818 | F11: 818 | G11: =VLOOKUP(A11,PPL!B:N,13,0) -> 818 | H11: =G11-F11 -> 0 | I11: =E11=G11 -> TRUE
A12: Reynold Samandi | B12: =VLOOKUP(A12,PPL!B:C,2,0) -> Marsila Mayanti Matiune | C12: =VLOOKUP(A12,PPL!B:D,3,0) -> Lasimran | D12: PPL | E12: 761 | F12: 761 | G12: =VLOOKUP(A12,PPL!B:N,13,0) -> 761 | H12: =G12-F12 -> 0 | I12: =E12=G12 -> TRUE
A13: Aini Nurotul Salsa | B13: =VLOOKUP(A13,PPL!B:C,2,0) -> Husnul Khotimah Hasri | C13: =VLOOKUP(A13,PPL!B:D,3,0) -> Oliv | D13: PPL | E13: 850 | F13: 850 | G13: =VLOOKUP(A13,PPL!B:N,13,0) -> 850 | H13: =G13-F13 -> 0 | I13: =E13=G13 -> TRUE
... A132: Muchsin Latif | B132: =VLOOKUP(A132,PPL!B:C,2,0) -> Deasy Natalia Hengkeng | C132: =VLOOKUP(A132,PPL!B:D,3,0) -> Alfian | D132: PPL | E132: 1082 | F132: 1082 | G132: =VLOOKUP(A132,PPL!B:N,13,0) -> 1082 | H132: =G132-F132 -> 0 | I132: =E132=G132 -> TRUE
A133: Erfina K. Lamaju | B133: - | C133: =VLOOKUP(A133,PML!A:B,2,0) -> Meidy | D133: PML | E133: 3454 | F133: 3763 | G133: =VLOOKUP(A133,PML!A:K,11,0) -> 3944 | H133: =G133-F133 -> 181 | I133: =E133=G133 -> FALSE
A134: Marsila Mayanti Matiune | B134: - | C134: =VLOOKUP(A134,PML!A:B,2,0) -> Lasimran | D134: PML | E134: 3601 | F134: 3921 | G134: =VLOOKUP(A134,PML!A:K,11,0) -> 4131 | H134: =G134-F134 -> 210 | I134: =E134=G134 -> FALSE
A135: Husnul Khotimah Hasri | B135: - | C135: =VLOOKUP(A135,PML!A:B,2,0) -> Oliv | D135: PML | E135: 5646 | F135: 5651 | G135: =VLOOKUP(A135,PML!A:K,11,0) -> 5691 | H135: =G135-F135 -> 40 | I135: =E135=G135 -> FALSE
A136: Retnowati Sumelung | B136: - | C136: =VLOOKUP(A136,PML!A:B,2,0) -> Vera | D136: PML | E136: 5465 | F136: 5448 | G136: =VLOOKUP(A136,PML!A:K,11,0) -> 5673 | H136: =G136-F136 -> 225 | I136: =E136=G136 -> FALSE
A137: Mariska Langi | B137: - | C137: =VLOOKUP(A137,PML!A:B,2,0) -> NurAlamsyah | D137: PML | E137: 5112 | F137: 5338 | G137: =VLOOKUP(A137,PML!A:K,11,0) -> 5470 | H137: =G137-F137 -> 132 | I137: =E137=G137 -> FALSE
A138: Lina Aprilia | B138: - | C138: =VLOOKUP(A138,PML!A:B,2,0) -> Firly | D138: PML | E138: 3797 | F138: 3922 | G138: =VLOOKUP(A138,PML!A:K,11,0) -> 4018 | H138: =G138-F138 -> 96 | I138: =E138=G138 -> FALSE
A139: Syerel Sinta Tulus | B139: - | C139: =VLOOKUP(A139,PML!A:B,2,0) -> Handoko | D139: PML | E139: 3036 | F139: 3070 | G139: =VLOOKUP(A139,PML!A:K,11,0) -> 3054 | H139: =G139-F139 -> -16 | I139: =E139=G139 -> FALSE
A140: Emy Oktaviani Syah | B140: - | C140: =VLOOKUP(A140,PML!A:B,2,0) -> Rudy | D140: PML | E140: 4829 | F140: 4842 | G140: =VLOOKUP(A140,PML!A:K,11,0) -> 4859 | H140: =G140-F140 -> 17 | I140: =E140=G140 -> FALSE
A141: Syifa Fauziah Suleman | B141: - | C141: =VLOOKUP(A141,PML!A:B,2,0) -> Iska | D141: PML | E141: 4587 | F141: 4601 | G141: =VLOOKUP(A141,PML!A:K,11,0) -> 4594 | H141: =G141-F141 -> -7 | I141: =E141=G141 -> FALSE
A142: Ramli Minggu | B142: - | C142: =VLOOKUP(A142,PML!A:B,2,0) -> Puput | D142: PML | E142: 3677 | F142: 3785 | G142: =VLOOKUP(A142,PML!A:K,11,0) -> 3960 | H142: =G142-F142 -> 175 | I142: =E142=G142 -> FALSE
A143: Welmintje Lawendatu | B143: - | C143: =VLOOKUP(A143,PML!A:B,2,0) -> Ijan | D143: PML | E143: 3824 | F143: 3847 | G143: =VLOOKUP(A143,PML!A:K,11,0) -> 3687 | H143: =G143-F143 -> -160 | I143: =E143=G143 -> FALSE
A144: Yuche Lahay | B144: - | C144: =VLOOKUP(A144,PML!A:B,2,0) -> Uneth | D144: PML | E144: 4440 | F144: 4456 | G144: =VLOOKUP(A144,PML!A:K,11,0) -> 4463 | H144: =G144-F144 -> 7 | I144: =E144=G144 -> FALSE
... A151: Deasy Natalia Hengkeng | B151: - | C151: =VLOOKUP(A151,PML!A:B,2,0) -> Alfian | D151: PML | E151: 6094 | F151: 6098 | G151: =VLOOKUP(A151,PML!A:K,11,0) -> 6288 | H151: =G151-F151 -> 190 | I151: =E151=G151 -> FALSE
A152: MOHAMAD GOFAR | B152: =VLOOKUP(A152,PPL!B:C,2,0) -> Mariska Langi | C152: =VLOOKUP(A152,PPL!B:D,3,0) -> NurAlamsyah | D152: PPL | E152: 931 | F152: 931 | G152: =VLOOKUP(A152,PPL!B:N,13,0) -> 931 | H152: =G152-F152 -> 0 | I152: =E152=G152 -> TRUE
A153: Trivani Mundiahi | B153: =VLOOKUP(A153,PPL!B:C,2,0) -> Ramli Minggu | C153: =VLOOKUP(A153,PPL!B:D,3,0) -> Puput | D153: PPL | E153: 644 | F153: 644 | G153: =VLOOKUP(A153,PPL!B:N,13,0) -> 648 | H153: =G153-F153 -> 4 | I153: =E153=G153 -> FALSE
A154: Syaputra Nurhermawan Entengo | B154: =VLOOKUP(A154,PPL!B:C,2,0) -> Yuche Lahay | C154: =VLOOKUP(A154,PPL!B:D,3,0) -> Uneth | D154: PPL | E154: 684 | F154: 698 | G154: =VLOOKUP(A154,PPL!B:N,13,0) -> 708 | H154: =G154-F154 -> 10 | I154: =E154=G154 -> FALSE
A155: Elvira Nathania Wuntuan | B155: =VLOOKUP(A155,PPL!B:C,2,0) -> Lina Aprilia | C155: =VLOOKUP(A155,PPL!B:D,3,0) -> Firly | D155: PPL | E155: 810 | F155: 792 | G155: =VLOOKUP(A155,PPL!B:N,13,0) -> 856 | H155: =G155-F155 -> 64 | I155: =E155=G155 -> FALSE
A156: Rahmiyati Paramata | B156: =VLOOKUP(A156,PPL!B:C,2,0) -> Syifa Fauziah Suleman | C156: =VLOOKUP(A156,PPL!B:D,3,0) -> Iska | D156: PPL | E156: 1008 | F156: 1006 | G156: =VLOOKUP(A156,PPL!B:N,13,0) -> 1021 | H156: =G156-F156 -> 15 | I156: =E156=G156 -> FALSE
A157: Meyske Helen maelissa | B157: =VLOOKUP(A157,PPL!B:C,2,0) -> Retnowati Sumelung | C157: =VLOOKUP(A157,PPL!B:D,3,0) -> Vera | D157: PPL | E157: 640 | F157: 689 | G157: =VLOOKUP(A157,PPL!B:N,13,0) -> 712 | H157: =G157-F157 -> 23 | I157: =E157=G157 -> FALSE
A158: Jullia Sarah Esmeralda Sandil | B158: =VLOOKUP(A158,PPL!B:C,2,0) -> Marsila Mayanti Matiune | C158: =VLOOKUP(A158,PPL!B:D,3,0) -> Lasimran | D158: PPL | E158: 640 | F158: 641 | G158: =VLOOKUP(A158,PPL!B:N,13,0) -> 644 | H158: =G158-F158 -> 3 | I158: =E158=G158 -> FALSE

Sheet UB
A1: NAMA PERUSAHAAN | B1: PJ | C1: STATUS
A2: MEMBANGUN SULUT MAJU PERSERODA, PT | C2: =VLOOKUP(A2,'UB-DATA'!D:J,7,0) -> #N/A
A3: MEMBANGUN SULUT MAJU PERSERODA DISINGKAT MESMA | C3: =VLOOKUP(A3,'UB-DATA'!D:J,7,0) -> open
A4: AGEN JUAL BERAS <RAIS> | B4: Tim 1 Alfian | C4: =VLOOKUP(A4,'UB-DATA'!D:J,7,0) -> #N/A
A5: TEMPAT JUAL PAKAN TERNAK | B5: Tim 1 Alfian | C5: =VLOOKUP(A5,'UB-DATA'!D:J,7,0) -> #N/A
A6: SAMUDRA MANDIRI SENTOSA PT | B6: Tim 1 Alfian | C6: =VLOOKUP(A6,'UB-DATA'!D:J,7,0) -> open
A7: JASA ANGKUTAN | B7: Tim 1 Alfian | C7: =VLOOKUP(A7,'UB-DATA'!D:J,7,0) -> #N/A
A8: BANK MANDIRI TASPEN | B8: Tim 1 Alfian | C8: =VLOOKUP(A8,'UB-DATA'!D:J,7,0) -> open
A9: AWILTON NYIUR INTERNASIONAL | B9: Tim 1 Alfian | C9: =VLOOKUP(A9,'UB-DATA'!D:J,7,0) -> open
A10: MAPALUS MAKAWANUA CHARCOAL -INDUSTRY, PT | B10: Tim 1 Alfian | C10: =VLOOKUP(A10,'UB-DATA'!D:J,7,0) -> #N/A
A11: PT Adira Dinamika Multi Finance Tbk, Kantor Representative Office Sulawesi | B11: Tim 1 Alfian | C11: =VLOOKUP(A11,'UB-DATA'!D:J,7,0) -> open
A12: DWI MATRA SAKTI, PT | B12: Tim 1 Alfian | C12: =VLOOKUP(A12,'UB-DATA'!D:J,7,0) -> #N/A
A13: SARI USAHA MANDIRI, PT | B13: Tim 1 Alfian | C13: =VLOOKUP(A13,'UB-DATA'!D:J,7,0) -> #N/A
A14: pt. bANK rAKYAT iNDONESIA UNIT SAGERAT | B14: Tim 1 Alfian | C14: =VLOOKUP(A14,'UB-DATA'!D:J,7,0) -> open
A15: SINAR KARYA MEGA PERSADA | B15: Tim 1 Alfian | C15: =VLOOKUP(A15,'UB-DATA'!D:J,7,0) -> open
... A126: IKAN SAMUDERA INDONESIA | B126: Tim 4 Handoko | C126: =VLOOKUP(A126,'UB-DATA'!D:J,7,0) -> submitted respondent
A127: INDO LAUTAN MAS, PT | C127: =VLOOKUP(A127,'UB-DATA'!D:J,7,0) -> submitted respondent
A128: MARINA NUSANTARA SELARAS, PT | C128: =VLOOKUP(A128,'UB-DATA'!D:J,7,0) -> submitted respondent
A129: ANPING SEAFOOD INDONESIA | C129: =VLOOKUP(A129,'UB-DATA'!D:J,7,0) -> submitted respondent
A130: PALMA MARINAIO NUSANTARA, pt | C130: =VLOOKUP(A130,'UB-DATA'!D:J,7,0) -> submitted respondent
A131: FUTAI SULAWESI UTARA PT | C131: =VLOOKUP(A131,'UB-DATA'!D:J,7,0) -> submitted respondent
A132: CITRA SAMUDRA NUSANTARA | C132: =VLOOKUP(A132,'UB-DATA'!D:J,7,0) -> open
A133: PT Multi Duta Cipta | C133: =VLOOKUP(A133,'UB-DATA'!D:J,7,0) -> open
A134: PT. IKAN SAMUDRA INDONESIA | C134: =VLOOKUP(A134,'UB-DATA'!D:J,7,0) -> #N/A
A135: PT. TONG BITUNG JAYA | C135: =VLOOKUP(A135,'UB-DATA'!D:J,7,0) -> #N/A
A136: PT. KABASARAN TRITIS INTERNASIONAL | C136: =VLOOKUP(A136,'UB-DATA'!D:J,7,0) -> #N/A
A137: SAMUDRA ULAM NUSANTARA | C137: =VLOOKUP(A137,'UB-DATA'!D:J,7,0) -> submitted respondent
A138: INDO JAYA FORTUNA, PT | C138: =VLOOKUP(A138,'UB-DATA'!D:J,7,0) -> #N/A

Sheet UB-DATA
A1: Fasih Logo
A2: Surveys
A3: SENSUS EKONOMI 2026 - UB
A4: pencacahan
A5: PENDATAAN
A6: 9 Mei 2026 s.d 31 Agu 2026
A7: 43 hari tersisa
A8: Kembali ke Aplikasi LamaDocumentation
A9: UMUM
A10: Ringkasan
A11: Lookup
A12: PERIODE
A13: PENDATAAN
A14: 46023
A15: Ctrl+B
A16: PENDATAAN
A17: 09 Mei 2026 - 31 Agt 2026
A18: UMUM
A19: Dasbor
A20: Data
A21: MANAJEMEN SAMPEL
A22: Tarik Sampel
A23: MANAJEMEN AKSES
A24: Petugas
A25: Ctrl+S
A26: Data
... A28: Status Assignment
A29: 137
A30: Semua
A31: Tipe: Target
A32: Penugasan: Semua
A33: Aksi Lainnya
A34: Kolom
B35: Kode Identitas | C35: Nama Perusahaan | D35: Nama Komersial | E35: Alamat | F35: ID SBR | G35: NIB | H35: Email | I35: Kategori 2025 | J35: Status | K35: Mode | L35: Petugas Saat Ini | M35: Keterangan
B36: 7172000000000000 - UB - 79 | C36: BANK SULUT | D36: BANK SULUT | E36: PASAR TRADISIONAL | F36: 97410902 | G36: - | H36: - | I36: - | J36: open | K36: CAWI | L36: ahlipoeto | M36: - | N36: =VLOOKUP(C36,UB!A:A,1,0) -> BANK SULUT
B37: 7172000000000000 - UB - 797172000000000000 - UB - 79 | L37: Pencacah
B38: 7172000000000000 - UB - 74 | C38: BANK BRI | D38: - | E38: - | F38: 97410201 | G38: - | H38: - | I38: L | J38: submitted by pencacah | K38: CAPI | L38: meidy | M38: - | N38: =VLOOKUP(C38,UB!A:A,1,0) -> BANK BRI
L39: Pengawas
B40: 7172000000000000 - UB - 77 | C40: BANK KUMAPAN | D40: - | E40: - | F40: 97410590 | G40: - | H40: - | I40: L | J40: submitted by pencacah | K40: CAPI | L40: meidy | M40: - | N40: =VLOOKUP(C40,UB!A:A,1,0) -> BANK KUMAPAN
L41: Pengawas
...

Sheet PPL
A1: email | B1: PPL | C1: PML | D1: TASKFORCE | E1: total | F1: APPROVED BY Pengawas | G1: DRAFT | H1: OPEN | I1: REJECTED BY Pengawas | J1: REVOKED BY Pengawas | K1: SUBMITTED BY Pencacah | L1: SUBMITTED RESPONDENT | M1: DIDATA | N1: PROGRESS | O1: PERSENTASE | P1: TARGET HARIAN | Q1: TDK
A2: devitasimpaen11@gmail.com | B2: Devita Maria Kristi Simpaen | C2: Erfina K. Lamaju | D2: =VLOOKUP(C2,PML!A:B,2,0) -> Meidy | E2: =SUMIF(DATA!$A:$A,PPL!$A2,DATA!C:C) -> 686 | F2: =SUMIF(DATA!$A:$A,PPL!$A2,DATA!D:D) -> 679 | G2: =SUMIF(DATA!$A:$A,PPL!$A2,DATA!E:E) -> 0 | H2: =SUMIF(DATA!$A:$A,PPL!$A2,DATA!F:F) -> 0 | I2: =SUMIF(DATA!$A:$A,PPL!$A2,DATA!G:G) -> 5 | J2: =SUMIF(DATA!$A:$A,PPL!$A2,DATA!H:H) -> 0 | K2: =SUMIF(DATA!$A:$A,PPL!$A2,DATA!I:I) -> 2 | L2: =SUMIF(DATA!$A:$A,PPL!$A2,DATA!J:J) -> 0 | M2: =N2-Q2 -> 429 | N2: =F2+I2+J2+K2+L2 -> 686 | O2: =(N2/E2)*100 -> 100 | P2: =CEILING((E2-N2)/1,1) -> 0 | Q2: =SUMIF(DATA!A:A,PPL!A2,DATA!N:N) -> 257
A3: glaudiasasindua@gmail.com | B3: Glaudia Enjela Sasindua | C3: Marsila Mayanti Matiune | D3: =VLOOKUP(C3,PML!A:B,2,0) -> Lasimran | E3: =SUMIF(DATA!$A:$A,PPL!$A3,DATA!C:C) -> 643 | F3: =SUMIF(DATA!$A:$A,PPL!$A3,DATA!D:D) -> 591 | G3: =SUMIF(DATA!$A:$A,PPL!$A3,DATA!E:E) -> 0 | H3: =SUMIF(DATA!$A:$A,PPL!$A3,DATA!F:F) -> 0 | I3: =SUMIF(DATA!$A:$A,PPL!$A3,DATA!G:G) -> 0 | J3: =SUMIF(DATA!$A:$A,PPL!$A3,DATA!H:H) -> 0 | K3: =SUMIF(DATA!$A:$A,PPL!$A3,DATA!I:I) -> 52 | L3: =SUMIF(DATA!$A:$A,PPL!$A3,DATA!J:J) -> 0 | M3: =N3-Q3 -> 405 | N3: =F3+I3+J3+K3+L3 -> 643 | O3: =(N3/E3)*100 -> 100 | P3: =CEILING((E3-N3)/1,1) -> 0 | Q3: =SUMIF(DATA!A:A,PPL!A3,DATA!N:N) -> 238
A4: shyntiamangosa@gmail.com | B4: Yunita Shyntia Mangosa | C4: Erfina K. Lamaju | D4: =VLOOKUP(C4,PML!A:B,2,0) -> Meidy | E4: =SUMIF(DATA!$A:$A,PPL!$A4,DATA!C:C) -> 733 | F4: =SUMIF(DATA!$A:$A,PPL!$A4,DATA!D:D) -> 733 | G4: =SUMIF(DATA!$A:$A,PPL!$A4,DATA!E:E) -> 0 | H4: =SUMIF(DATA!$A:$A,PPL!$A4,DATA!F:F) -> 0 | I4: =SUMIF(DATA!$A:$A,PPL!$A4,DATA!G:G) -> 0 | J4: =SUMIF(DATA!$A:$A,PPL!$A4,DATA!H:H) -> 0 | K4: =SUMIF(DATA!$A:$A,PPL!$A4,DATA!I:I) -> 0 | L4: =SUMIF(DATA!$A:$A,PPL!$A4,DATA!J:J) -> 0 | M4: =N4-Q4 -> 427 | N4: =F4+I4+J4+K4+L4 -> 733 | O4: =(N4/E4)*100 -> 100 | P4: =CEILING((E4-N4)/1,1) -> 0 | Q4: =SUMIF(DATA!A:A,PPL!A4,DATA!N:N) -> 306
A5: brigithaelorapetiunaung@gmail.com | B5: Rini Yani Aalung | C5: Erfina K. Lamaju | D5: =VLOOKUP(C5,PML!A:B,2,0) -> Meidy | E5: =SUMIF(DATA!$A:$A,PPL!$A5,DATA!C:C) -> 706 | F5: =SUMIF(DATA!$A:$A,PPL!$A5,DATA!D:D) -> 611 | G5: =SUMIF(DATA!$A:$A,PPL!$A5,DATA!E:E) -> 0 | H5: =SUMIF(DATA!$A:$A,PPL!$A5,DATA!F:F) -> 0 | I5: =SUMIF(DATA!$A:$A,PPL!$A5,DATA!G:G) -> 0 | J5: =SUMIF(DATA!$A:$A,PPL!$A5,DATA!H:H) -> 0 | K5: =SUMIF(DATA!$A:$A,PPL!$A5,DATA!I:I) -> 95 | L5: =SUMIF(DATA!$A:$A,PPL!$A5,DATA!J:J) -> 0 | M5: =N5-Q5 -> 303 | N5: =F5+I5+J5+K5+L5 -> 706 | O5: =(N5/E5)*100 -> 100 | P5: =CEILING((E5-N5)/1,1) -> 0 | Q5: =SUMIF(DATA!A:A,PPL!A5,DATA!N:N) -> 403
A6: malinytumandung@gmail.com | B6: Maliny Ocnelia Tumandung | C6: Erfina K. Lamaju | D6: =VLOOKUP(C6,PML!A:B,2,0) -> Meidy | E6: =SUMIF(DATA!$A:$A,PPL!$A6,DATA!C:C) -> 818 | F6: =SUMIF(DATA!$A:$A,PPL!$A6,DATA!D:D) -> 491 | G6: =SUMIF(DATA!$A:$A,PPL!$A6,DATA!E:E) -> 1 | H6: =SUMIF(DATA!$A:$A,PPL!$A6,DATA!F:F) -> 0 | I6: =SUMIF(DATA!$A:$A,PPL!$A6,DATA!G:G) -> 20 | J6: =SUMIF(DATA!$A:$A,PPL!$A6,DATA!H:H) -> 0 | K6: =SUMIF(DATA!$A:$A,PPL!$A6,DATA!I:I) -> 306 | L6: =SUMIF(DATA!$A:$A,PPL!$A6,DATA!J:J) -> 0 | M6: =N6-Q6 -> 516 | N6: =F6+I6+J6+K6+L6 -> 817 | O6: =(N6/E6)*100 -> 99.877751 | P6: =CEILING((E6-N6)/1,1) -> 1 | Q6: =SUMIF(DATA!A:A,PPL!A6,DATA!N:N) -> 301
A7: zairastudio26@gmail.com | B7: Sumirani Gude | C7: Erfina K. Lamaju | D7: =VLOOKUP(C7,PML!A:B,2,0) -> Meidy | E7: =SUMIF(DATA!$A:$A,PPL!$A7,DATA!C:C) -> 656 | F7: =SUMIF(DATA!$A:$A,PPL!$A7,DATA!D:D) -> 303 | G7: =SUMIF(DATA!$A:$A,PPL!$A7,DATA!E:E) -> 0 | H7: =SUMIF(DATA!$A:$A,PPL!$A7,DATA!F:F) -> 0 | I7: =SUMIF(DATA!$A:$A,PPL!$A7,DATA!G:G) -> 0 | J7: =SUMIF(DATA!$A:$A,PPL!$A7,DATA!H:H) -> 0 | K7: =SUMIF(DATA!$A:$A,PPL!$A7,DATA!I:I) -> 353 | L7: =SUMIF(DATA!$A:$A,PPL!$A7,DATA!J:J) -> 0 | M7: =N7-Q7 -> 399 | N7: =F7+I7+J7+K7+L7 -> 656 | O7: =(N7/E7)*100 -> 100 | P7: =CEILING((E7-N7)/1,1) -> 0 | Q7: =SUMIF(DATA!A:A,PPL!A7,DATA!N:N) -> 257
A8: ingkiriwangmey76@gmail.com | B8: Meily Ingkiriwang | C8: Marsila Mayanti Matiune | D8: =VLOOKUP(C8,PML!A:B,2,0) -> Lasimran | E8: =SUMIF(DATA!$A:$A,PPL!$A8,DATA!C:C) -> 733 | F8: =SUMIF(DATA!$A:$A,PPL!$A8,DATA!D:D) -> 733 | G8: =SUMIF(DATA!$A:$A,PPL!$A8,DATA!E:E) -> 0 | H8: =SUMIF(DATA!$A:$A,PPL!$A8,DATA!F:F) -> 0 | I8: =SUMIF(DATA!$A:$A,PPL!$A8,DATA!G:G) -> 0 | J8: =SUMIF(DATA!$A:$A,PPL!$A8,DATA!H:H) -> 0 | K8: =SUMIF(DATA!$A:$A,PPL!$A8,DATA!I:I) -> 0 | L8: =SUMIF(DATA!$A:$A,PPL!$A8,DATA!J:J) -> 0 | M8: =N8-Q8 -> 490 | N8: =F8+I8+J8+K8+L8 -> 733 | O8: =(N8/E8)*100 -> 100 | P8: =CEILING((E8-N8)/1,1) -> 0 | Q8: =SUMIF(DATA!A:A,PPL!A8,DATA!N:N) -> 243
A9: mimimustamin@gmail.com | B9: Misnawati Mustamin | C9: Erfina K. Lamaju | D9: =VLOOKUP(C9,PML!A:B,2,0) -> Meidy | E9: =SUMIF(DATA!$A:$A,PPL!$A9,DATA!C:C) -> 782 | F9: =SUMIF(DATA!$A:$A,PPL!$A9,DATA!D:D) -> 458 | G9: =SUMIF(DATA!$A:$A,PPL!$A9,DATA!E:E) -> 1 | H9: =SUMIF(DATA!$A:$A,PPL!$A9,DATA!F:F) -> 0 | I9: =SUMIF(DATA!$A:$A,PPL!$A9,DATA!G:G) -> 2 | J9: =SUMIF(DATA!$A:$A,PPL!$A9,DATA!H:H) -> 0 | K9: =SUMIF(DATA!$A:$A,PPL!$A9,DATA!I:I) -> 321 | L9: =SUMIF(DATA!$A:$A,PPL!$A9,DATA!J:J) -> 0 | M9: =N9-Q9 -> 437 | N9: =F9+I9+J9+K9+L9 -> 781 | O9: =(N9/E9)*100 -> 99.872123 | P9: =CEILING((E9-N9)/1,1) -> 1 | Q9: =SUMIF(DATA!A:A,PPL!A9,DATA!N:N) -> 344
A10: adelheitsadara9@gmail.com | B10: Gersony Sirus Kakondo | C10: Marsila Mayanti Matiune | D10: =VLOOKUP(C10,PML!A:B,2,0) -> Lasimran | E10: =SUMIF(DATA!$A:$A,PPL!$A10,DATA!C:C) -> 734 | F10: =SUMIF(DATA!$A:$A,PPL!$A10,DATA!D:D) -> 464 | G10: =SUMIF(DATA!$A:$A,PPL!$A10,DATA!E:E) -> 0 | H10: =SUMIF(DATA!$A:$A,PPL!$A10,DATA!F:F) -> 0 | I10: =SUMIF(DATA!$A:$A,PPL!$A10,DATA!G:G) -> 0 | J10: =SUMIF(DATA!$A:$A,PPL!$A10,DATA!H:H) -> 0 | K10: =SUMIF(DATA!$A:$A,PPL!$A10,DATA!I:I) -> 270 | L10: =SUMIF(DATA!$A:$A,PPL!$A10,DATA!J:J) -> 0 | M10: =N10-Q10 -> 424 | N10: =F10+I10+J10+K10+L10 -> 734 | O10: =(N10/E10)*100 -> 100 | P10: =CEILING((E10-N10)/1,1) -> 0 | Q10: =SUMIF(DATA!A:A,PPL!A10,DATA!N:N) -> 310
A11: elsadaylohigee@gmail.com | B11: Tesalonika Lohige | C11: Marsila Mayanti Matiune | D11: =VLOOKUP(C11,PML!A:B,2,0) -> Lasimran | E11: =SUMIF(DATA!$A:$A,PPL!$A11,DATA!C:C) -> 818 | F11: =SUMIF(DATA!$A:$A,PPL!$A11,DATA!D:D) -> 818 | G11: =SUMIF(DATA!$A:$A,PPL!$A11,DATA!E:E) -> 0 | H11: =SUMIF(DATA!$A:$A,PPL!$A11,DATA!F:F) -> 0 | I11: =SUMIF(DATA!$A:$A,PPL!$A11,DATA!G:G) -> 0 | J11: =SUMIF(DATA!$A:$A,PPL!$A11,DATA!H:H) -> 0 | K11: =SUMIF(DATA!$A:$A,PPL!$A11,DATA!I:I) -> 0 | L11: =SUMIF(DATA!$A:$A,PPL!$A11,DATA!J:J) -> 0 | M11: =N11-Q11 -> 434 | N11: =F11+I11+J11+K11+L11 -> 818 | O11: =(N11/E11)*100 -> 100 | P11: =CEILING((E11-N11)/1,1) -> 0 | Q11: =SUMIF(DATA!A:A,PPL!A11,DATA!N:N) -> 384
A12: reynoldsamandi01@gmail.com | B12: Reynold Samandi | C12: Marsila Mayanti Matiune | D12: =VLOOKUP(C12,PML!A:B,2,0) -> Lasimran | E12: =SUMIF(DATA!$A:$A,PPL!$A12,DATA!C:C) -> 761 | F12: =SUMIF(DATA!$A:$A,PPL!$A12,DATA!D:D) -> 436 | G12: =SUMIF(DATA!$A:$A,PPL!$A12,DATA!E:E) -> 0 | H12: =SUMIF(DATA!$A:$A,PPL!$A12,DATA!F:F) -> 0 | I12: =SUMIF(DATA!$A:$A,PPL!$A12,DATA!G:G) -> 0 | J12: =SUMIF(DATA!$A:$A,PPL!$A12,DATA!H:H) -> 0 | K12: =SUMIF(DATA!$A:$A,PPL!$A12,DATA!I:I) -> 325 | L12: =SUMIF(DATA!$A:$A,PPL!$A12,DATA!J:J) -> 0 | M12: =N12-Q12 -> 394 | N12: =F12+I12+J12+K12+L12 -> 761 | O12: =(N12/E12)*100 -> 100 | P12: =CEILING((E12-N12)/1,1) -> 0 | Q12: =SUMIF(DATA!A:A,PPL!A12,DATA!N:N) -> 367
A13: nurotulsalsa@gmail.com | B13: Aini Nurotul Salsa | C13: Husnul Khotimah Hasri | D13: =VLOOKUP(C13,PML!A:B,2,0) -> Oliv | E13: =SUMIF(DATA!$A:$A,PPL!$A13,DATA!C:C) -> 850 | F13: =SUMIF(DATA!$A:$A,PPL!$A13,DATA!D:D) -> 822 | G13: =SUMIF(DATA!$A:$A,PPL!$A13,DATA!E:E) -> 0 | H13: =SUMIF(DATA!$A:$A,PPL!$A13,DATA!F:F) -> 0 | I13: =SUMIF(DATA!$A:$A,PPL!$A13,DATA!G:G) -> 2 | J13: =SUMIF(DATA!$A:$A,PPL!$A13,DATA!H:H) -> 0 | K13: =SUMIF(DATA!$A:$A,PPL!$A13,DATA!I:I) -> 26 | L13: =SUMIF(DATA!$A:$A,PPL!$A13,DATA!J:J) -> 0 | M13: =N13-Q13 -> 503 | N13: =F13+I13+J13+K13+L13 -> 850 | O13: =(N13/E13)*100 -> 100 | P13: =CEILING((E13-N13)/1,1) -> 0 | Q13: =SUMIF(DATA!A:A,PPL!A13,DATA!N:N) -> 347
... A139: kvnkshe10jni@gmail.com | B139: Jullia Sarah Esmeralda Sandil | C139: Marsila Mayanti Matiune | D139: =VLOOKUP(C139,PML!A:B,2,0) -> Lasimran | E139: =SUMIF(DATA!$A:$A,PPL!$A139,DATA!C:C) -> 644 | F139: =SUMIF(DATA!$A:$A,PPL!$A139,DATA!D:D) -> 381 | G139: =SUMIF(DATA!$A:$A,PPL!$A139,DATA!E:E) -> 0 | H139: =SUMIF(DATA!$A:$A,PPL!$A139,DATA!F:F) -> 0 | I139: =SUMIF(DATA!$A:$A,PPL!$A139,DATA!G:G) -> 0 | J139: =SUMIF(DATA!$A:$A,PPL!$A139,DATA!H:H) -> 1 | K139: =SUMIF(DATA!$A:$A,PPL!$A139,DATA!I:I) -> 262 | L139: =SUMIF(DATA!$A:$A,PPL!$A139,DATA!J:J) -> 0 | M139: =N139-Q139 -> 371 | N139: =F139+I139+J139+K139+L139 -> 644 | O139: =(N139/E139)*100 -> 100 | P139: =CEILING((E139-N139)/1,1) -> 0 | Q139: =SUMIF(DATA!A:A,PPL!A139,DATA!N:N) -> 273

Sheet PML
A1: PML | B1: TASKFORCE | C1: total | D1: APPROVED BY Pengawas | E1: DRAFT | F1: OPEN | G1: REJECTED BY Pengawas | H1: REVOKED BY Pengawas | I1: SUBMITTED BY Pencacah | J1: SUBMITTED RESPONDENT | K1: PROGRESS | L1: PERSENTASE
A2: Erfina K. Lamaju | B2: Meidy | C2: =SUMIF(PPL!$C:$C,PML!$A2,PPL!E:E) -> 5274 | D2: =SUMIF(PPL!$C:$C,PML!$A2,PPL!F:F) -> 3944 | E2: =SUMIF(PPL!$C:$C,PML!$A2,PPL!G:G) -> 2 | F2: =SUMIF(PPL!$C:$C,PML!$A2,PPL!H:H) -> 0 | G2: =SUMIF(PPL!$C:$C,PML!$A2,PPL!I:I) -> 32 | H2: =SUMIF(PPL!$C:$C,PML!$A2,PPL!J:J) -> 0 | I2: =SUMIF(PPL!$C:$C,PML!$A2,PPL!K:K) -> 1296 | J2: =SUMIF(PPL!$C:$C,PML!$A2,PPL!L:L) -> 0 | K2: =D2 -> 3944 | L2: =(SUM(D2)/C2)*100 -> 74.781949
A3: Marsila Mayanti Matiune | B3: Lasimran | C3: =SUMIF(PPL!$C:$C,PML!$A3,PPL!E:E) -> 5172 | D3: =SUMIF(PPL!$C:$C,PML!$A3,PPL!F:F) -> 4131 | E3: =SUMIF(PPL!$C:$C,PML!$A3,PPL!G:G) -> 0 | F3: =SUMIF(PPL!$C:$C,PML!$A3,PPL!H:H) -> 0 | G3: =SUMIF(PPL!$C:$C,PML!$A3,PPL!I:I) -> 7 | H3: =SUMIF(PPL!$C:$C,PML!$A3,PPL!J:J) -> 1 | I3: =SUMIF(PPL!$C:$C,PML!$A3,PPL!K:K) -> 1033 | J3: =SUMIF(PPL!$C:$C,PML!$A3,PPL!L:L) -> 0 | K3: =D3 -> 4131 | L3: =(SUM(D3)/C3)*100 -> 79.87239
A4: Husnul Khotimah Hasri | B4: Oliv | C4: =SUMIF(PPL!$C:$C,PML!$A4,PPL!E:E) -> 6319 | D4: =SUMIF(PPL!$C:$C,PML!$A4,PPL!F:F) -> 5691 | E4: =SUMIF(PPL!$C:$C,PML!$A4,PPL!G:G) -> 0 | F4: =SUMIF(PPL!$C:$C,PML!$A4,PPL!H:H) -> 0 | G4: =SUMIF(PPL!$C:$C,PML!$A4,PPL!I:I) -> 2 | H4: =SUMIF(PPL!$C:$C,PML!$A4,PPL!J:J) -> 0 | I4: =SUMIF(PPL!$C:$C,PML!$A4,PPL!K:K) -> 625 | J4: =SUMIF(PPL!$C:$C,PML!$A4,PPL!L:L) -> 1 | K4: =D4 -> 5691 | L4: =(SUM(D4)/C4)*100 -> 90.061719
A5: Retnowati Sumelung | B5: Vera | C5: =SUMIF(PPL!$C:$C,PML!$A5,PPL!E:E) -> 7076 | D5: =SUMIF(PPL!$C:$C,PML!$A5,PPL!F:F) -> 5673 | E5: =SUMIF(PPL!$C:$C,PML!$A5,PPL!G:G) -> 220 | F5: =SUMIF(PPL!$C:$C,PML!$A5,PPL!H:H) -> 0 | G5: =SUMIF(PPL!$C:$C,PML!$A5,PPL!I:I) -> 22 | H5: =SUMIF(PPL!$C:$C,PML!$A5,PPL!J:J) -> 9 | I5: =SUMIF(PPL!$C:$C,PML!$A5,PPL!K:K) -> 1152 | J5: =SUMIF(PPL!$C:$C,PML!$A5,PPL!L:L) -> 0 | K5: =D5 -> 5673 | L5: =(SUM(D5)/C5)*100 -> 80.172414
A6: Mariska Langi | B6: NurAlamsyah | C6: =SUMIF(PPL!$C:$C,PML!$A6,PPL!E:E) -> 6639 | D6: =SUMIF(PPL!$C:$C,PML!$A6,PPL!F:F) -> 5470 | E6: =SUMIF(PPL!$C:$C,PML!$A6,PPL!G:G) -> 29 | F6: =SUMIF(PPL!$C:$C,PML!$A6,PPL!H:H) -> 0 | G6: =SUMIF(PPL!$C:$C,PML!$A6,PPL!I:I) -> 17 | H6: =SUMIF(PPL!$C:$C,PML!$A6,PPL!J:J) -> 1 | I6: =SUMIF(PPL!$C:$C,PML!$A6,PPL!K:K) -> 1122 | J6: =SUMIF(PPL!$C:$C,PML!$A6,PPL!L:L) -> 0 | K6: =D6 -> 5470 | L6: =(SUM(D6)/C6)*100 -> 82.391926
A7: Lina Aprilia | B7: Firly | C7: =SUMIF(PPL!$C:$C,PML!$A7,PPL!E:E) -> 7098 | D7: =SUMIF(PPL!$C:$C,PML!$A7,PPL!F:F) -> 4018 | E7: =SUMIF(PPL!$C:$C,PML!$A7,PPL!G:G) -> 90 | F7: =SUMIF(PPL!$C:$C,PML!$A7,PPL!H:H) -> 0 | G7: =SUMIF(PPL!$C:$C,PML!$A7,PPL!I:I) -> 149 | H7: =SUMIF(PPL!$C:$C,PML!$A7,PPL!J:J) -> 4 | I7: =SUMIF(PPL!$C:$C,PML!$A7,PPL!K:K) -> 2836 | J7: =SUMIF(PPL!$C:$C,PML!$A7,PPL!L:L) -> 1 | K7: =D7 -> 4018 | L7: =(SUM(D7)/C7)*100 -> 56.607495
A8: Syerel Sinta Tulus | B8: Handoko | C8: =SUMIF(PPL!$C:$C,PML!$A8,PPL!E:E) -> 6230 | D8: =SUMIF(PPL!$C:$C,PML!$A8,PPL!F:F) -> 3054 | E8: =SUMIF(PPL!$C:$C,PML!$A8,PPL!G:G) -> 202 | F8: =SUMIF(PPL!$C:$C,PML!$A8,PPL!H:H) -> 0 | G8: =SUMIF(PPL!$C:$C,PML!$A8,PPL!I:I) -> 157 | H8: =SUMIF(PPL!$C:$C,PML!$A8,PPL!J:J) -> 14 | I8: =SUMIF(PPL!$C:$C,PML!$A8,PPL!K:K) -> 2803 | J8: =SUMIF(PPL!$C:$C,PML!$A8,PPL!L:L) -> 0 | K8: =D8 -> 3054 | L8: =(SUM(D8)/C8)*100 -> 49.020867
A9: Emy Oktaviani Syah | B9: Rudy | C9: =SUMIF(PPL!$C:$C,PML!$A9,PPL!E:E) -> 6745 | D9: =SUMIF(PPL!$C:$C,PML!$A9,PPL!F:F) -> 4859 | E9: =SUMIF(PPL!$C:$C,PML!$A9,PPL!G:G) -> 1 | F9: =SUMIF(PPL!$C:$C,PML!$A9,PPL!H:H) -> 0 | G9: =SUMIF(PPL!$C:$C,PML!$A9,PPL!I:I) -> 189 | H9: =SUMIF(PPL!$C:$C,PML!$A9,PPL!J:J) -> 4 | I9: =SUMIF(PPL!$C:$C,PML!$A9,PPL!K:K) -> 1692 | J9: =SUMIF(PPL!$C:$C,PML!$A9,PPL!L:L) -> 0 | K9: =D9 -> 4859 | L9: =(SUM(D9)/C9)*100 -> 72.038547
A10: Syifa Fauziah Suleman | B10: Iska | C10: =SUMIF(PPL!$C:$C,PML!$A10,PPL!E:E) -> 6263 | D10: =SUMIF(PPL!$C:$C,PML!$A10,PPL!F:F) -> 4594 | E10: =SUMIF(PPL!$C:$C,PML!$A10,PPL!G:G) -> 6 | F10: =SUMIF(PPL!$C:$C,PML!$A10,PPL!H:H) -> 0 | G10: =SUMIF(PPL!$C:$C,PML!$A10,PPL!I:I) -> 45 | H10: =SUMIF(PPL!$C:$C,PML!$A10,PPL!J:J) -> 1 | I10: =SUMIF(PPL!$C:$C,PML!$A10,PPL!K:K) -> 1617 | J10: =SUMIF(PPL!$C:$C,PML!$A10,PPL!L:L) -> 0 | K10: =D10 -> 4594 | L10: =(SUM(D10)/C10)*100 -> 73.351429
A11: Ramli Minggu | B11: Puput | C11: =SUMIF(PPL!$C:$C,PML!$A11,PPL!E:E) -> 4655 | D11: =SUMIF(PPL!$C:$C,PML!$A11,PPL!F:F) -> 3960 | E11: =SUMIF(PPL!$C:$C,PML!$A11,PPL!G:G) -> 0 | F11: =SUMIF(PPL!$C:$C,PML!$A11,PPL!H:H) -> 0 | G11: =SUMIF(PPL!$C:$C,PML!$A11,PPL!I:I) -> 121 | H11: =SUMIF(PPL!$C:$C,PML!$A11,PPL!J:J) -> 3 | I11: =SUMIF(PPL!$C:$C,PML!$A11,PPL!K:K) -> 571 | J11: =SUMIF(PPL!$C:$C,PML!$A11,PPL!L:L) -> 0 | K11: =D11 -> 3960 | L11: =(SUM(D11)/C11)*100 -> 85.069817
A12: Welmintje Lawendatu | B12: Ijan | C12: =SUMIF(PPL!$C:$C,PML!$A12,PPL!E:E) -> 3948 | D12: =SUMIF(PPL!$C:$C,PML!$A12,PPL!F:F) -> 3687 | E12: =SUMIF(PPL!$C:$C,PML!$A12,PPL!G:G) -> 6 | F12: =SUMIF(PPL!$C:$C,PML!$A12,PPL!H:H) -> 0 | G12: =SUMIF(PPL!$C:$C,PML!$A12,PPL!I:I) -> 64 | H12: =SUMIF(PPL!$C:$C,PML!$A12,PPL!J:J) -> 10 | I12: =SUMIF(PPL!$C:$C,PML!$A12,PPL!K:K) -> 181 | J12: =SUMIF(PPL!$C:$C,PML!$A12,PPL!L:L) -> 0 | K12: =D12 -> 3687 | L12: =(SUM(D12)/C12)*100 -> 93.389058
A13: Yuche Lahay | B13: Uneth | C13: =SUMIF(PPL!$C:$C,PML!$A13,PPL!E:E) -> 4679 | D13: =SUMIF(PPL!$C:$C,PML!$A13,PPL!F:F) -> 4463 | E13: =SUMIF(PPL!$C:$C,PML!$A13,PPL!G:G) -> 38 | F13: =SUMIF(PPL!$C:$C,PML!$A13,PPL!H:H) -> 0 | G13: =SUMIF(PPL!$C:$C,PML!$A13,PPL!I:I) -> 10 | H13: =SUMIF(PPL!$C:$C,PML!$A13,PPL!J:J) -> 2 | I13: =SUMIF(PPL!$C:$C,PML!$A13,PPL!K:K) -> 166 | J13: =SUMIF(PPL!$C:$C,PML!$A13,PPL!L:L) -> 0 | K13: =D13 -> 4463 | L13: =(SUM(D13)/C13)*100 -> 95.383629
... A20: Deasy Natalia Hengkeng | B20: Alfian | C20: =SUMIF(PPL!$C:$C,PML!$A20,PPL!E:E) -> 6288 | D20: =SUMIF(PPL!$C:$C,PML!$A20,PPL!F:F) -> 6288 | E20: =SUMIF(PPL!$C:$C,PML!$A20,PPL!G:G) -> 0 | F20: =SUMIF(PPL!$C:$C,PML!$A20,PPL!H:H) -> 0 | G20: =SUMIF(PPL!$C:$C,PML!$A20,PPL!I:I) -> 0 | H20: =SUMIF(PPL!$C:$C,PML!$A20,PPL!J:J) -> 0 | I20: =SUMIF(PPL!$C:$C,PML!$A20,PPL!K:K) -> 0 | J20: =SUMIF(PPL!$C:$C,PML!$A20,PPL!L:L) -> 0 | K20: =D20 -> 6288 | L20: =(SUM(D20)/C20)*100 -> 100

Sheet TARGET
A1: TANGGAL | B1: HARI | C1: TARGET
A2: 46188 | B2: =TEXT(A2,"DDDD") -> Monday | C2: =(COUNTA($B$2:B2)*1.66667) -> 1.66667
A3: 46189 | B3: =TEXT(A3,"DDDD") -> Tuesday | C3: =(COUNTA($B$2:B3)*1.66667) -> 3.33334
A4: 46190 | B4: =TEXT(A4,"DDDD") -> Wednesday | C4: =(COUNTA($B$2:B4)*1.66667) -> 5.00001
A5: 46191 | B5: =TEXT(A5,"DDDD") -> Thursday | C5: =(COUNTA($B$2:B5)*1.66667) -> 6.66668
A6: 46192 | B6: =TEXT(A6,"DDDD") -> Friday | C6: =(COUNTA($B$2:B6)*1.66667) -> 8.33335
A7: 46193 | B7: =TEXT(A7,"DDDD") -> Saturday | C7: =(COUNTA($B$2:B7)*1.66667) -> 10.00002
A8: 46194 | C8: =(COUNTA($B$2:B8)*1.66667) -> 10.00002
A9: 46195 | B9: =TEXT(A9,"DDDD") -> Monday | C9: =(COUNTA($B$2:B9)*1.66667) -> 11.66669
A10: 46196 | B10: =TEXT(A10,"DDDD") -> Tuesday | C10: =(COUNTA($B$2:B10)*1.66667) -> 13.33336
A11: 46197 | B11: =TEXT(A11,"DDDD") -> Wednesday | C11: =(COUNTA($B$2:B11)*1.66667) -> 15.00003
A12: 46198 | B12: =TEXT(A12,"DDDD") -> Thursday | C12: =(COUNTA($B$2:B12)*1.66667) -> 16.6667
A13: 46199 | B13: =TEXT(A13,"DDDD") -> Friday | C13: =(COUNTA($B$2:B13)*1.66667) -> 18.33337
A14: 46200 | B14: =TEXT(A14,"DDDD") -> Saturday | C14: =(COUNTA($B$2:B14)*1.66667) -> 20.00004
A15: 46201 | C15: =(COUNTA($B$2:B15)*1.66667) -> 20.00004
A16: 46202 | B16: =TEXT(A16,"DDDD") -> Monday | C16: =(COUNTA($B$2:B16)*1.66667) -> 21.66671
A17: 46203 | B17: =TEXT(A17,"DDDD") -> Tuesday | C17: =(COUNTA($B$2:B17)*1.66667) -> 23.33338
A18: 46204 | B18: =TEXT(A18,"DDDD") -> Wednesday | C18: =(COUNTA($B$2:B18)*1.66667) -> 25.00005
A19: 46205 | B19: =TEXT(A19,"DDDD") -> Thursday | C19: =(COUNTA($B$2:B19)*1.66667) -> 26.66672
A20: 46206 | B20: =TEXT(A20,"DDDD") -> Friday | C20: =(COUNTA($B$2:B20)*1.66667) -> 28.33339
A21: 46207 | B21: =TEXT(A21,"DDDD") -> Saturday | C21: =(COUNTA($B$2:B21)*1.66667) -> 30.00006
A22: 46208 | C22: =(COUNTA($B$2:B22)*1.66667) -> 30.00006
A23: 46209 | B23: =TEXT(A23,"DDDD") -> Monday | C23: =(COUNTA($B$2:B23)*1.66667) -> 31.66673
A24: 46210 | B24: =TEXT(A24,"DDDD") -> Tuesday | C24: =(COUNTA($B$2:B24)*1.66667) -> 33.3334
A25: 46211 | B25: =TEXT(A25,"DDDD") -> Wednesday | C25: =(COUNTA($B$2:B25)*1.66667) -> 35.00007
A26: 46212 | B26: =TEXT(A26,"DDDD") -> Thursday | C26: =(COUNTA($B$2:B26)*1.66667) -> 36.66674
A27: 46213 | B27: =TEXT(A27,"DDDD") -> Friday | C27: =(COUNTA($B$2:B27)*1.66667) -> 38.33341
A28: 46214 | B28: =TEXT(A28,"DDDD") -> Saturday | C28: =(COUNTA($B$2:B28)*1.66667) -> 40.00008
A29: 46215 | C29: =(COUNTA($B$2:B29)*1.66667) -> 40.00008
A30: 46216 | B30: =TEXT(A30,"DDDD") -> Monday | C30: =(COUNTA($B$2:B30)*1.66667) -> 41.66675
A31: 46217 | B31: =TEXT(A31,"DDDD") -> Tuesday | C31: =(COUNTA($B$2:B31)*1.66667) -> 43.33342
A32: 46218 | B32: =TEXT(A32,"DDDD") -> Wednesday | C32: =(COUNTA($B$2:B32)*1.66667) -> 45.00009
A33: 46219 | B33: =TEXT(A33,"DDDD") -> Thursday | C33: =(COUNTA($B$2:B33)*1.66667) -> 46.66676
A34: 46220 | B34: =TEXT(A34,"DDDD") -> Friday | C34: =(COUNTA($B$2:B34)*1.66667) -> 48.33343
A35: 46221 | B35: =TEXT(A35,"DDDD") -> Saturday | C35: =(COUNTA($B$2:B35)*1.66667) -> 50.0001
A36: 46222 | C36: =(COUNTA($B$2:B36)*1.66667) -> 50.0001
A37: 46223 | B37: =TEXT(A37,"DDDD") -> Monday | C37: =(COUNTA($B$2:B37)*1.66667) -> 51.66677
A38: 46224 | B38: =TEXT(A38,"DDDD") -> Tuesday | C38: =(COUNTA($B$2:B38)*1.66667) -> 53.33344
A39: 46225 | B39: =TEXT(A39,"DDDD") -> Wednesday | C39: =(COUNTA($B$2:B39)*1.66667) -> 55.00011
A40: 46226 | B40: =TEXT(A40,"DDDD") -> Thursday | C40: =(COUNTA($B$2:B40)*1.66667) -> 56.66678
...

Sheet INFO
A1: TANGGAL_DATA
A2: =TODAY()-1 -> 46274
